<?xml version="1.0" ?>
<robot name="mcc_simple" xmlns:xacro="http://ros.org/wiki/xacro">
<!-- Base -->
<link name="base">
    <visual>
        <geometry><mesh filename="package://ocs2_robotic_assets/resources/mcc/meshes_umv_robots/mini_vision_body.dae"/></geometry>
        <origin rpy="0.0 0.0 0.0" xyz="0.0 0.0 0.0"/>
    </visual>
    <collision>
        <geometry><box size="0.30 0.20 0.10"/></geometry>
        <origin rpy="0 0 0" xyz="0 0 0.01"/>
    </collision>
    <collision>
        <geometry><sphere radius="0.05"/></geometry>
        <origin rpy="0 0 0" xyz="0.12 0.06 0.01"/>
    </collision>
    <collision>
        <geometry><sphere radius="0.05"/></geometry>
        <origin rpy="0 0 0" xyz="0.12 -0.06 0.01"/>
    </collision>
    <collision>
        <geometry><sphere radius="0.05"/></geometry>
        <origin rpy="0 0 0" xyz="-0.12 0.06 0.01"/>
    </collision>
    <collision>
        <geometry><sphere radius="0.05"/></geometry>
        <origin rpy="0 0 0" xyz="-0.12 -0.06 0.01"/>
    </collision>
</link>

<link name="base_inertia">
    <inertial>
        <origin rpy="0.0 0.0 0.0" xyz="0.0 0.0 0.0"/>
        <mass value="2.0108"/>
        <inertia ixx="0.00857941247522831" ixy="0.0" ixz="0.0" iyy="0.01695774495601654" iyz="0.0" izz="0.02178366482257843"/>
    </inertial>
</link>
<joint name="base_inertia_joint" type="fixed">
    <origin rpy="0 0 0" xyz="0 0 0"/>
    <parent link="base"/>
    <child link="base_inertia"/>
</joint>


<!-- RF Leg -->
<!-- RF Hip and HAA -->
<joint name="RF_HAA" type="revolute">
    <axis xyz="1 0 0"/>
    <origin rpy="0 0 0" xyz="0.14775 -0.049 0.0"/>
    <parent link="base"/>
    <child link="abduct_fr"/>
    <limit effort="18" lower="-1.5" upper="1.5" velocity="41"/>
</joint>

<link name="abduct_fr">
    <inertial>
        <origin rpy="-0.14322670270153148 0.0 0.0" xyz="0.054999999701976776 -0.035999998450279236 0.0"/>
        <mass value="0.72171"/>
        <inertia ixx="0.0006684197191130838" ixy="0.0" ixz="0.0" iyy="0.0009136285321805158" iyz="0.0" izz="0.0006799108814448116"/>
    </inertial>
    <visual>
        <geometry>
            <mesh filename="package://ocs2_robotic_assets/resources/mcc/meshes_umv_robots/mini_vision_abd.dae"/>
        </geometry>
        <origin rpy="0.0 0.0 0.0" xyz="0.0 0.0 0.0"/>
    </visual>
    <!-- <collision>
        <geometry><cylinder length ="0.025" radius = "0.05"/></geometry>
        <origin rpy="1.57079632679 0.0 0.0" xyz="0.052 -0.02 0.0"/>
    </collision> -->
</link>

<!-- RF Thigh and HFE -->
<joint name="RF_HFE" type="revolute">
    <axis xyz="0 -1 0"/>
    <origin rpy="0.0 0.0 0.0" xyz="0.055 -0.019 0.00"/>
    <parent link="abduct_fr"/>
    <child link="thigh_fr"/>
    <limit effort="18" lower="-2.6" upper="2.6" velocity="41"/>
</joint>

<link name="thigh_fr">
    <inertial>
        <origin rpy="0.0045182957616685115 2.362822272461429e-05 -0.5261015946763354" xyz="0.0 0.01600000075995922 -0.019999999552965164"/>
        <mass value="1.78775"/>
        <inertia ixx="0.016169944734410774" ixy="0.0" ixz="0.0" iyy="0.013982671534532799" iyz="0.0" izz="0.0036247394131612427"/>
    </inertial>
    <visual>
        <geometry>
            <mesh filename="package://ocs2_robotic_assets/resources/mcc/meshes_umv_robots/mini_vision_upper_leg.dae"/>
        </geometry>
        <origin rpy="0.0 0.0 0.0" xyz="0.0 0.0 0.0"/>
    </visual>
    <collision>
        <geometry>
            <cylinder length ="0.17" radius = "0.015"/>
        </geometry>
        <origin rpy="0 0 0" xyz="0 -0.05 -0.092"/>
    </collision>
</link>

<!-- RF Shank and KFE -->
<joint name="RF_KFE" type="revolute">
    <axis xyz="0 -1 0"/>
    <origin rpy="0.0 0 0.0" xyz="0.0 -0.049 -0.2085"/>
    <parent link="thigh_fr"/>
    <child link="shank_fr"/>
    <limit effort="28" lower="-2.7" upper="2.7" velocity="26.8"/>
</joint>

<link name="shank_fr">
    <inertial>
        <origin rpy="0.004289740172676915 0.006306204145582139 -0.027637395801773934" xyz="0.0 0.0 -0.061000000685453415"/>
        <mass value="0.11739"/>
        <inertia ixx="0.0009354346953270918" ixy="0.0" ixz="0.0" iyy="0.0009460580678116367" iyz="0.0" izz="3.225696978240411e-05"/>
    </inertial>
    <visual>
        <geometry>
            <mesh filename="package://ocs2_robotic_assets/resources/mcc/meshes_umv_robots/lower_leg.dae"/>
        </geometry>
        <origin rpy="0.0 0.0 0.0" xyz="0.0 0.0 0.0"/>
    </visual>
    <collision>
        <geometry>
            <cylinder length ="0.1" radius = "0.01"/>
        </geometry>
        <origin rpy="0 0 0" xyz="0 0 -0.1"/>
    </collision>
</link>
<!-- LF Leg -->
<!-- LF Hip and HAA -->
<joint name="LF_HAA" type="revolute">
    <axis xyz="1 0 0"/>
    <origin rpy="0 0 0" xyz="0.14775 0.049 0.0"/>
    <parent link="base"/>
    <child link="abduct_fl"/>
    <limit effort="18" lower="-1.5" upper="1.5" velocity="41"/>
</joint>

<link name="abduct_fl">
    <inertial>
        <origin rpy="-0.2709449962748738 0.006153037312526255 -0.003866471872195021" xyz="0.054999999701976776 0.035999998450279236 0.0"/>
        <mass value="0.72171"/>
        <inertia ixx="0.0013867244638617689" ixy="0.0" ixz="0.0" iyy="0.0007683276938983429" iyz="0.0" izz="0.0014850795178781473"/>
    </inertial>
    <visual>
        <geometry><mesh filename="package://ocs2_robotic_assets/resources/mcc/meshes_umv_robots/mini_vision_abd.dae"/></geometry>
        <origin rpy="3.141592 0.0 0.0" xyz="0.0 0.0 0.0"/>
    </visual>
    <!-- <collision>
        <geometry><cylinder length ="0.025" radius = "0.05"/></geometry>
        <origin rpy="1.57079632679 0.0 0.0" xyz="0.052 0.02 0.0"/>
    </collision> -->
</link>

<!-- LF Thigh and HFE -->
<joint name="LF_HFE" type="revolute">
    <axis xyz="0 -1 0"/>
    <origin rpy="0.0 0.0 0.0" xyz="0.055 0.019 0.00"/>
    <parent link="abduct_fl"/>
    <child link="thigh_fl"/>
    <limit effort="18" lower="-2.6" upper="2.6" velocity="41"/>
</joint>

<link name="thigh_fl">
    <inertial>
        <origin rpy="0.10166259372793007 -0.0003441332492841731 0.21465928688985958" xyz="0.0 0.01600000075995922 -0.019999999552965164"/>
        <mass value="1.78775"/>
        <inertia ixx="0.011918476516988349" ixy="0.0" ixz="0.0" iyy="0.011838328278892297" iyz="0.0" izz="0.001516054464559224"/>
    </inertial>
    <visual>
        <geometry>
            <mesh filename="package://ocs2_robotic_assets/resources/mcc/meshes_umv_robots/mini_vision_upper_leg.dae"/>
        </geometry>
        <origin rpy="0.0 0 3.141592" xyz="0.0 0.0 0.0"/>
    </visual>
    <collision>
        <geometry><cylinder length ="0.17" radius = "0.015"/></geometry>
        <origin rpy="0 0 0" xyz="0 0.05 -0.092"/>
    </collision>
</link>

<!-- LF Shank and KFE -->
<joint name="LF_KFE" type="revolute">
    <axis xyz="0 -1 0"/>
    <origin rpy="0.0 0 0.0" xyz="0.0 0.049 -0.2085"/>
    <parent link="thigh_fl"/>
    <child link="shank_fl"/>
    <limit effort="28" lower="-2.7" upper="2.7" velocity="26.8"/>
</joint>

<link name="shank_fl">
    <inertial>
        <origin rpy="0.004289055358260185 -0.006306222466212041 0.02763739181927516" xyz="0.0 0.0 -0.061000000685453415"/>
        <mass value="0.11739"/>
        <inertia ixx="0.0009354346956011618" ixy="0.0" ixz="0.0" iyy="0.0009460580675964972" iyz="0.0" izz="3.225696972347361e-05"/>
    </inertial>
    <visual>
        <geometry>
            <mesh filename="package://ocs2_robotic_assets/resources/mcc/meshes_umv_robots/lower_leg.dae"/>
        </geometry>
        <origin rpy="0.0 0.0 0.0" xyz="0.0 0.0 0.0"/>
    </visual>
    <collision>
        <geometry>
            <cylinder length ="0.1" radius = "0.01"/>
        </geometry>
        <origin rpy="0 0 0" xyz="0 0 -0.1"/>
    </collision>
</link>
<!-- RH Leg -->
<!-- RH Hip and HAA -->
<joint name="RH_HAA" type="revolute">
    <axis xyz="-1 0 0"/>
    <origin rpy="0 3.141592 0" xyz="-0.14775 -0.049 0.0"/>
    <parent link="base"/>
    <child link="abduct_hr"/>
    <limit effort="18" lower="-1.5" upper="1.5" velocity="41"/>
</joint>

<link name="abduct_hr">
    <inertial>
        <origin rpy="0.2709449961180592 -0.006152559313835404 -0.0038668232386669388" xyz="0.054999999701976776 -0.035999998450279236 0.0"/>
        <mass value="0.72171"/>
        <inertia ixx="0.001386724464398052" ixy="0.0" ixz="0.0" iyy="0.0007683276922718103" iyz="0.0" izz="0.0014850795189683954"/>
    </inertial>
    <visual>
        <geometry>
            <mesh filename="package://ocs2_robotic_assets/resources/mcc/meshes_umv_robots/mini_vision_abd.dae"/>
        </geometry>
        <origin rpy="0.0 0.0 0.0" xyz="0.0 0.0 0.0"/>
    </visual>
    <!-- <collision>
        <geometry><cylinder length ="0.025" radius = "0.05"/></geometry>
        <origin rpy="1.57079632679 0.0 0.0" xyz="0.052 -0.02 0.0"/>
    </collision> -->
</link>

<!-- RH Thigh and HFE -->
<joint name="RH_HFE" type="revolute">
    <axis xyz="0 -1 0"/>
    <origin rpy="0.0 3.141592 0.0" xyz="0.055 -0.019 0.00"/>
    <parent link="abduct_hr"/>
    <child link="thigh_hr"/>
    <limit effort="18" lower="-2.6" upper="2.6" velocity="41"/>
</joint>

<link name="thigh_hr">
    <inertial>
        <origin rpy="0.0045182957616685115 2.362822272461429e-05 -0.5261015946763354" xyz="0.0 0.01600000075995922 -0.019999999552965164"/>
        <mass value="1.78775"/>
        <inertia ixx="0.016169944734410774" ixy="0.0" ixz="0.0" iyy="0.013982671534532799" iyz="0.0" izz="0.0036247394131612427"/>
    </inertial>
    <visual>
        <geometry>
            <mesh filename="package://ocs2_robotic_assets/resources/mcc/meshes_umv_robots/mini_vision_upper_leg.dae"/>
        </geometry>
        <origin rpy="0.0 0.0 0.0" xyz="0.0 0.0 0.0"/>
    </visual>
    <collision>
        <geometry>
            <cylinder length ="0.17" radius = "0.015"/>
        </geometry>
        <origin rpy="0 0 0" xyz="0 -0.05 -0.092"/>
    </collision>
</link>

<!-- RH Shank and KFE -->
<joint name="RH_KFE" type="revolute">
    <axis xyz="0 -1 0"/>
    <origin rpy="0.0 0 0.0" xyz="0.0 -0.049 -0.2085"/>
    <parent link="thigh_hr"/>
    <child link="shank_hr"/>
    <limit effort="28" lower="-2.7" upper="2.7" velocity="26.8"/>
</joint>

<link name="shank_hr">
    <inertial>
        <origin rpy="0.004289740172676915 0.006306204145582139 -0.027637395801773934" xyz="0.0 0.0 -0.061000000685453415"/>
        <mass value="0.11739"/>
        <inertia ixx="0.0009354346953270918" ixy="0.0" ixz="0.0" iyy="0.0009460580678116367" iyz="0.0" izz="3.225696978240411e-05"/>
    </inertial>
    <visual>
        <geometry>
            <mesh filename="package://ocs2_robotic_assets/resources/mcc/meshes_umv_robots/lower_leg.dae"/>
        </geometry>
        <origin rpy="0.0 0.0 0.0" xyz="0.0 0.0 0.0"/>
    </visual>
    <collision>
        <geometry>
            <cylinder length ="0.1" radius = "0.01"/>
        </geometry>
        <origin rpy="0 0 0" xyz="0 0 -0.1"/>
    </collision>
</link>

<!-- LH Leg -->
<!-- LH Hip and HAA -->
<joint name="LH_HAA" type="revolute">
    <axis xyz="-1 0 0"/>
    <origin rpy="0 3.141592 0" xyz="-0.14775 0.049 0.0"/>
    <parent link="base"/>
    <child link="abduct_hl"/>
    <limit effort="18" lower="-1.5" upper="1.5" velocity="41"/>
</joint>

<link name="abduct_hl">
    <inertial>
        <origin rpy="-0.2709449962748738 0.006153037312526255 -0.003866471872195021" xyz="0.054999999701976776 0.035999998450279236 0.0"/>
        <mass value="0.72171"/>
        <inertia ixx="0.0013867244638617689" ixy="0.0" ixz="0.0" iyy="0.0007683276938983429" iyz="0.0" izz="0.0014850795178781473"/>
    </inertial>
    <visual>
        <geometry> <mesh filename="package://ocs2_robotic_assets/resources/mcc/meshes_umv_robots/mini_vision_abd.dae"/> </geometry>
        <origin rpy="3.141592 0.0 0.0" xyz="0.0 0.0 0.0"/>
    </visual>
    <!-- <collision>
        <geometry><cylinder length ="0.025" radius = "0.05"/></geometry>
        <origin rpy="1.57079632679 0.0 0.0" xyz="0.052 0.02 0.0"/>
    </collision> -->
</link>

<!-- LH Thigh and HFE -->
<joint name="LH_HFE" type="revolute">
    <axis xyz="0 -1 0"/>
    <origin rpy="0.0 3.141592 0.0" xyz="0.055 0.019 0.00"/>
    <parent link="abduct_hl"/>
    <child link="thigh_hl"/>
    <limit effort="18" lower="-2.6" upper="2.6" velocity="41"/>
</joint>

<link name="thigh_hl">
    <inertial>
        <origin rpy="0.10166259372793007 -0.0003441332492841731 0.21465928688985958" xyz="0.0 0.01600000075995922 -0.019999999552965164"/>
        <mass value="1.78775"/>
        <inertia ixx="0.011918476516988349" ixy="0.0" ixz="0.0" iyy="0.011838328278892297" iyz="0.0" izz="0.001516054464559224"/>
    </inertial>
    <visual>
        <geometry>
            <mesh filename="package://ocs2_robotic_assets/resources/mcc/meshes_umv_robots/mini_vision_upper_leg.dae"/>
        </geometry>
        <origin rpy="0.0 0 3.141592" xyz="0.0 0.0 0.0"/>
    </visual>
    <collision>
        <geometry>
            <cylinder length ="0.17" radius = "0.015"/>
        </geometry>
        <origin rpy="0 0 0" xyz="0 0.05 -0.092"/>
    </collision>
</link>

<!-- LH Shank and KFE -->
<joint name="LH_KFE" type="revolute">
    <axis xyz="0 -1 0"/>
    <origin rpy="0.0 0 0.0" xyz="0.0 0.049 -0.2085"/>
    <parent link="thigh_hl"/>
    <child link="shank_hl"/>
    <limit effort="28" lower="-2.7" upper="2.7" velocity="26.8"/>
</joint>

<link name="shank_hl">
    <inertial>
        <origin rpy="0.004289055358260185 -0.006306222466212041 0.02763739181927516" xyz="0.0 0.0 -0.061000000685453415"/>
        <mass value="0.11739"/>
        <inertia ixx="0.0009354346956011618" ixy="0.0" ixz="0.0" iyy="0.0009460580675964972" iyz="0.0" izz="3.225696972347361e-05"/>
    </inertial>
    <visual>
        <geometry>
            <mesh filename="package://ocs2_robotic_assets/resources/mcc/meshes_umv_robots/lower_leg.dae"/>
        </geometry>
        <origin rpy="0.0 0.0 3.141592" xyz="0.0 0.0 0.0"/>
    </visual>
    <collision>
        <geometry>
            <cylinder length ="0.1" radius = "0.01"/>
        </geometry>
        <origin rpy="0 0 0" xyz="0 0 -0.1"/>
    </collision>
</link>

<!-- LH FOOT -->
<joint name="LH_shank_fixed_LH_FOOT" type="fixed">
    <parent link="shank_hl"/>
    <child link="LH_FOOT"/>
    <origin rpy="0.0 0.0 0.0" xyz="0.0 0.0 -0.22"/>
</joint>

<link name="LH_FOOT">
    <collision>
        <origin xyz="0 0.0 0.024"/>
        <geometry><sphere radius="0.0202"/></geometry>
    </collision>
    <inertial>
        <origin rpy="0.0 0.0 0.0" xyz="0.0 0.0 0.0"/>
        <mass value="0.04945"/>
        <inertia ixx="3.655422551673837e-05" ixy="0.0" ixz="0.0" iyy="3.655422551673837e-05" iyz="0.0" izz="8.071028787526302e-06"/>
    </inertial>
</link>


<!-- RH FOOT -->
<joint name="RH_shank_fixed_RH_FOOT" type="fixed">
    <parent link="shank_hr"/>
    <child link="RH_FOOT"/>
    <origin rpy="0.0 0.0 0.0" xyz="0.0 0.0 -0.22"/>
</joint>

<link name="RH_FOOT">
    <collision>
        <origin xyz="0 0.0 0.024"/>
        <geometry><sphere radius="0.0202"/></geometry>
    </collision>
    <inertial>
        <origin rpy="0.0 0.0 0.0" xyz="0.0 0.0 -0.0"/>
        <mass value="0.04945"/>
        <inertia ixx="3.655422551673837e-05" ixy="0.0" ixz="0.0" iyy="3.655422551673837e-05" iyz="0.0" izz="8.071028787526302e-06"/>
    </inertial>
</link>

<!-- LF FOOT -->
<joint name="LF_shank_fixed_LF_FOOT" type="fixed">
    <parent link="shank_fl"/>
    <child link="LF_FOOT"/>
    <origin rpy="0.0 0.0 0.0" xyz="0.0 0.0 -0.22"/>
</joint>

<link name="LF_FOOT">
    <collision>
        <origin xyz="0 0.0 0.024"/>
        <geometry><sphere radius="0.0202"/></geometry>
    </collision>
    <inertial>
        <origin rpy="0.0 0.0 0.0" xyz="0.0 0.0 0.0"/>
        <mass value="0.04945"/>
        <inertia ixx="3.655422551673837e-05" ixy="0.0" ixz="0.0" iyy="3.655422551673837e-05" iyz="0.0" izz="8.071028787526302e-06"/>
    </inertial>
</link>


<!-- RF FOOT -->
<joint name="RF_shank_fixed_RF_FOOT" type="fixed">
    <parent link="shank_fr"/>
    <child link="RF_FOOT"/>
    <origin rpy="0.0 0.0 0.0" xyz="0.0 0.0 -0.22"/>
</joint>

<link name="RF_FOOT">
    <collision>
        <origin xyz="0 0.0 0.024"/>
        <geometry><sphere radius="0.0202"/></geometry>
    </collision>
    <inertial>
        <origin rpy="0.0 0.0 0.0" xyz="0.0 0.0 0.0"/>
        <mass value="0.04945"/>
        <inertia ixx="3.655422551673837e-05" ixy="0.0" ixz="0.0" iyy="3.655422551673837e-05" iyz="0.0" izz="8.071028787526302e-06"/>
    </inertial>
</link>


</robot>
