<?xml version="1.0" ?>
<robot name="mini_cheetah_vision" xmlns:xacro="http://ros.org/wiki/xacro">
    <link name="base">
        <visual>
            <geometry>
                <mesh filename="package://ocs2_robotic_assets/resources/mcc/meshes/mini_vision_base.dae"/>
            </geometry>
            <origin rpy="0.0 0.0 0.0" xyz="0.0 0.0 0.0"/>
        </visual>
        <collision>
            <geometry>
                <mesh filename="package://ocs2_robotic_assets/resources/mcc/meshes/mini_vision_base.dae"/>
            </geometry>
            <origin rpy="0 0 0" xyz="0 0 0"/>
        </collision>
    </link>
    <link name="base_inertia">
          <inertial>
              <mass value="3.3"/>
              <origin xyz="0.0 0.0 0.0"/>
              <inertia ixx="0.011253" ixy="0" ixz="0" iyy="0.362030" iyz="0" izz="0.042673"/>
          </inertial>
    </link>
    <joint name="base_inertia_joint" type="fixed">
        <origin rpy="0 0 0" xyz="0 0 0"/>
        <parent link="base"/>
        <child link="base_inertia"/>
    </joint>

    <!--!!!!!!!!!!!! Front Right Leg !!!!!!!!!!!!!!!!!!!!!!!!!!!!!!!!!!!!-->
    <joint name="RF_HAA" type="revolute">
        <axis xyz="1 0 0"/>
        <origin rpy="0 0 0" xyz="0.14775 -0.049 0.0"/>
        <parent link="base"/>
        <child link="abduct_fr"/>
        <limit effort="17.0" lower="-3.14" upper="3.14" velocity="40.0"/>
    </joint>
    <link name="abduct_fr">
        <inertial>
            <mass value="0.54"/>
            <origin xyz="0.055 -0.036 0."/>
            <inertia ixx="0.000381" ixy="0.000058" ixz="0.00000045" iyy="0.000560" iyz="0.00000095" izz="0.000444"/>
        </inertial>
        <visual>
            <geometry>
                <mesh filename="package://ocs2_robotic_assets/resources/mcc/meshes/mini_vision_abd.dae"/>
            </geometry>
            <origin rpy="0.0 0.0 0.0" xyz="0.0 0.0 0.0"/>
        </visual>
        <collision>
            <geometry>
                <mesh filename="package://ocs2_robotic_assets/resources/mcc/meshes/mini_vision_abd.dae"/>
            </geometry>
            <origin rpy="0. 0. 0." xyz="0. 0 0"/>
        </collision>
    </link>

    <joint name="RF_HFE" type="revolute">
        <axis xyz="0 -1 0"/>
        <origin rpy="0.0 0.0 0.0" xyz="0.055 -0.019 0.00"/>
        <parent link="abduct_fr"/>
        <child link="thigh_fr"/>
        <limit effort="17.0" lower="-3.14" upper="3.14" velocity="40.0"/>
    </joint>
    <link name="thigh_fr">
        <inertial>
            <mass value="0.634"/>
            <origin xyz="0.0 0.016 -0.02"/>
            <inertia ixx="0.001983" ixy="0.000245" ixz="0.000013" iyy="0.002103" iyz="0.0000015" izz="0.000408"/>
        </inertial>
        <visual>
            <geometry>
                <mesh filename="package://ocs2_robotic_assets/resources/mcc/meshes/mini_vision_upper_leg.dae"/>
            </geometry>
            <origin rpy="0.0 0.0 0.0" xyz="0.0 0.0 0.0"/>
        </visual>
        <collision>
            <geometry>
                <mesh filename="package://ocs2_robotic_assets/resources/mcc/meshes/mini_vision_upper_leg.dae"/>
            </geometry>
            <origin rpy="0 0 0" xyz="0 0 0"/>
        </collision>
    </link>

    <joint name="RF_KFE" type="revolute">
        <axis xyz="0 -1 0"/>
        <origin rpy="0.0 0 0.0" xyz="0.0 -0.049 -0.2085"/>
        <parent link="thigh_fr"/>
        <child link="shank_fr"/>
        <limit effort="17.0" lower="-3.14" upper="3.14" velocity="40.0"/>
    </joint>
    <link name="shank_fr">
        <inertial>
            <mass value="0.064"/>
            <origin xyz="0.0 0.0 -0.061"/>
            <inertia ixx="0.000245" ixy="0" ixz="0.0" iyy="0.000248" iyz="0" izz="0.000006"/>
        </inertial>
        <visual>
            <geometry>
                <mesh filename="package://ocs2_robotic_assets/resources/mcc/meshes/lower_leg.dae"/>
            </geometry>
            <origin rpy="0.0 0.0 0.0" xyz="0.0 0.0 0.0"/>
        </visual>
        <collision>
            <geometry>
                <mesh filename="package://ocs2_robotic_assets/resources/mcc/meshes/lower_leg.dae"/>
            </geometry>
            <origin rpy="0 0 0" xyz="0 0 0"/>
        </collision>
    </link>

    <!--!!!!!!!!!!!! Front Left Leg !!!!!!!!!!!!!!!!!!!!!!!!!!!!!!!!!!!!-->
    <joint name="LF_HAA" type="revolute">
        <axis xyz="1 0 0"/>
        <origin rpy="0 0 0" xyz="0.14775 0.049 0.0"/>
        <parent link="base"/>
        <child link="abduct_fl"/>
        <limit effort="17.0" lower="-3.14" upper="3.14" velocity="40.0"/>
    </joint>
    <link name="abduct_fl">
        <inertial>
            <mass value="0.54"/>
            <origin xyz="0.055 0.036 0."/>
            <inertia ixx="0.000381" ixy="0.000058" ixz="0.00000045" iyy="0.000560" iyz="0.00000095" izz="0.000444"/>
        </inertial>
        <visual>
            <geometry>
                <mesh filename="package://ocs2_robotic_assets/resources/mcc/meshes/mini_vision_abd.dae"/>
            </geometry>
            <origin rpy="3.141592 0.0 0.0" xyz="0.0 0.0 0.0"/>
        </visual>
        <collision>
            <geometry>
                <mesh filename="package://ocs2_robotic_assets/resources/mcc/meshes/mini_vision_abd.dae"/>
            </geometry>
            <origin rpy="3.141592 0. 0." xyz="0. 0 0"/>
        </collision>
    </link>

    <joint name="LF_HFE" type="revolute">
        <axis xyz="0 -1 0"/>
        <origin rpy="0.0 0.0 0.0" xyz="0.055 0.019 0.00"/>
        <parent link="abduct_fl"/>
        <child link="thigh_fl"/>
        <limit effort="17.0" lower="-3.14" upper="3.14" velocity="40.0"/>
    </joint>
    <link name="thigh_fl">
        <inertial>
            <mass value="0.634"/>
            <origin xyz="0.0 0.016 -0.02"/>
            <inertia ixx="0.001983" ixy="0.000245" ixz="0.000013" iyy="0.002103" iyz="0.0000015" izz="0.000408"/>
        </inertial>
        <visual>
            <geometry>
                <mesh filename="package://ocs2_robotic_assets/resources/mcc/meshes/mini_vision_upper_leg.dae"/>
            </geometry>
            <origin rpy="0.0 0 3.141592" xyz="0.0 0.0 0.0"/>
        </visual>
        <collision>
            <geometry>
                <mesh filename="package://ocs2_robotic_assets/resources/mcc/meshes/mini_vision_upper_leg.dae"/>
            </geometry>
            <origin rpy="0 0 3.141592" xyz="0 0 0"/>
        </collision>
    </link>

    <joint name="LF_KFE" type="revolute">
        <axis xyz="0 -1 0"/>
        <origin rpy="0.0 0 0.0" xyz="0.0 0.049 -0.2085"/>
        <parent link="thigh_fl"/>
        <child link="shank_fl"/>
        <limit effort="17.0" lower="-3.14" upper="3.14" velocity="40.0"/>
    </joint>
    <link name="shank_fl">
        <inertial>
            <mass value="0.064"/>
            <origin xyz="0.0 0.0 -0.061"/>
            <inertia ixx="0.000245" ixy="0" ixz="0.0" iyy="0.000248" iyz="0" izz="0.000006"/>
        </inertial>
        <visual>
            <geometry>
                <mesh filename="package://ocs2_robotic_assets/resources/mcc/meshes/lower_leg.dae"/>
            </geometry>
            <origin rpy="0.0 0.0 3.141592" xyz="0.0 0.0 0.0"/>
        </visual>
        <collision>
            <geometry>
                <mesh filename="package://ocs2_robotic_assets/resources/mcc/meshes/lower_leg.dae"/>
            </geometry>
            <origin rpy="0 0 3.141592" xyz="0 0 0"/>
        </collision>
    </link>

    <!--!!!!!!!!!!!! Hind Right Leg !!!!!!!!!!!!!!!!!!!!!!!!!!!!!!!!!!!!-->
    <joint name="RH_HAA" type="revolute">
        <axis xyz="-1 0 0"/>
        <origin rpy="0 3.141592 0" xyz="-0.14775 -0.049 0.0"/>
        <parent link="base"/>
        <child link="abduct_hr"/>
        <limit effort="17.0" lower="-3.14" upper="3.14" velocity="40.0"/>
    </joint>
    <link name="abduct_hr">
        <inertial>
            <mass value="0.54"/>
            <origin xyz="0.055 -0.036 0."/>
            <inertia ixx="0.000381" ixy="0.000058" ixz="0.00000045" iyy="0.000560" iyz="0.00000095" izz="0.000444"/>
        </inertial>
        <visual>
            <geometry>
                <mesh filename="package://ocs2_robotic_assets/resources/mcc/meshes/mini_vision_abd.dae"/>
            </geometry>
            <origin rpy="0.0 0.0 0.0" xyz="0.0 0.0 0.0"/>
        </visual>
        <collision>
            <geometry>
                <mesh filename="package://ocs2_robotic_assets/resources/mcc/meshes/mini_vision_abd.dae"/>
            </geometry>
            <origin rpy="0. 0. 0." xyz="0. 0 0"/>
        </collision>
    </link>

    <joint name="RH_HFE" type="revolute">
        <axis xyz="0 -1 0"/>
        <origin rpy="0.0 3.141592 0.0" xyz="0.055 -0.019 0.00"/>
        <parent link="abduct_hr"/>
        <child link="thigh_hr"/>
        <limit effort="17.0" lower="-3.14" upper="3.14" velocity="40.0"/>
    </joint>
    <link name="thigh_hr">
        <inertial>
            <mass value="0.634"/>
            <origin xyz="0.0 0.016 -0.02"/>
            <inertia ixx="0.001983" ixy="0.000245" ixz="0.000013" iyy="0.002103" iyz="0.0000015" izz="0.000408"/>
        </inertial>
        <visual>
            <geometry>
                <mesh filename="package://ocs2_robotic_assets/resources/mcc/meshes/mini_vision_upper_leg.dae"/>
            </geometry>
            <origin rpy="0.0 0.0 0.0" xyz="0.0 0.0 0.0"/>
        </visual>
        <collision>
            <geometry>
                <mesh filename="package://ocs2_robotic_assets/resources/mcc/meshes/mini_vision_upper_leg.dae"/>
            </geometry>
            <origin rpy="0 0 0" xyz="0 0 0"/>
        </collision>
    </link>

    <joint name="RH_KFE" type="revolute">
        <axis xyz="0 -1 0"/>
        <origin rpy="0.0 0 0.0" xyz="0.0 -0.049 -0.2085"/>
        <parent link="thigh_hr"/>
        <child link="shank_hr"/>
        <limit effort="17.0" lower="-3.14" upper="3.14" velocity="40.0"/>
    </joint>
    <link name="shank_hr">
        <inertial>
            <mass value="0.064"/>
            <origin xyz="0.0 0.0 -0.061"/>
            <inertia ixx="0.000245" ixy="0" ixz="0.0" iyy="0.000248" iyz="0" izz="0.000006"/>
        </inertial>
        <visual>
            <geometry>
                <mesh filename="package://ocs2_robotic_assets/resources/mcc/meshes/lower_leg.dae"/>
            </geometry>
            <origin rpy="0.0 0.0 0.0" xyz="0.0 0.0 0.0"/>
        </visual>
        <collision>
            <geometry>
                <mesh filename="package://ocs2_robotic_assets/resources/mcc/meshes/lower_leg.dae"/>
            </geometry>
            <origin rpy="0 0 0" xyz="0 0 0"/>
        </collision>
    </link>

    <!--!!!!!!!!!!!! Hind Left Leg !!!!!!!!!!!!!!!!!!!!!!!!!!!!!!!!!!!!-->
    <joint name="LH_HAA" type="revolute">
        <axis xyz="-1 0 0"/>
        <origin rpy="0 3.141592 0" xyz="-0.14775 0.049 0.0"/>
        <parent link="base"/>
        <child link="abduct_hl"/>
        <limit effort="17.0" lower="-3.14" upper="3.14" velocity="40.0"/>
    </joint>
    <link name="abduct_hl">
        <inertial>
            <mass value="0.54"/>
            <origin xyz="0.055 0.036 0."/>
            <inertia ixx="0.000381" ixy="0.000058" ixz="0.00000045" iyy="0.000560" iyz="0.00000095" izz="0.000444"/>
        </inertial>
        <visual>
            <geometry>
                <mesh filename="package://ocs2_robotic_assets/resources/mcc/meshes/mini_vision_abd.dae"/>
            </geometry>
            <origin rpy="3.141592 0.0 0.0" xyz="0.0 0.0 0.0"/>
        </visual>
        <collision>
            <geometry>
                <mesh filename="package://ocs2_robotic_assets/resources/mcc/meshes/mini_vision_abd.dae"/>
            </geometry>
            <origin rpy="3.141592 0. 0." xyz="0. 0 0"/>
        </collision>
    </link>

    <joint name="LH_HFE" type="revolute">
        <axis xyz="0 -1 0"/>
        <origin rpy="0.0 3.141592 0.0" xyz="0.055 0.019 0.00"/>
        <parent link="abduct_hl"/>
        <child link="thigh_hl"/>
        <limit effort="17.0" lower="-3.14" upper="3.14" velocity="40.0"/>
    </joint>
    <link name="thigh_hl">
        <inertial>
            <mass value="0.634"/>
            <origin xyz="0.0 0.016 -0.02"/>
            <inertia ixx="0.001983" ixy="0.000245" ixz="0.000013" iyy="0.002103" iyz="0.0000015" izz="0.000408"/>
        </inertial>
        <visual>
            <geometry>
                <mesh filename="package://ocs2_robotic_assets/resources/mcc/meshes/mini_vision_upper_leg.dae"/>
            </geometry>
            <origin rpy="0.0 0 3.141592" xyz="0.0 0.0 0.0"/>
        </visual>
        <collision>
            <geometry>
                <mesh filename="package://ocs2_robotic_assets/resources/mcc/meshes/mini_vision_upper_leg.dae"/>
            </geometry>
            <origin rpy="0 0 3.141592" xyz="0 0 0"/>
        </collision>
    </link>

    <joint name="LH_KFE" type="revolute">
        <axis xyz="0 -1 0"/>
        <origin rpy="0.0 0 0.0" xyz="0.0 0.049 -0.2085"/>
        <parent link="thigh_hl"/>
        <child link="shank_hl"/>
        <limit effort="17.0" lower="-3.14" upper="3.14" velocity="40.0"/>
    </joint>
    <link name="shank_hl">
        <inertial>
            <mass value="0.064"/>
            <origin xyz="0.0 0.0 -0.061"/>
            <inertia ixx="0.000245" ixy="0" ixz="0.0" iyy="0.000248" iyz="0" izz="0.000006"/>
        </inertial>
        <visual>
            <geometry>
                <mesh filename="package://ocs2_robotic_assets/resources/mcc/meshes/lower_leg.dae"/>
            </geometry>
            <origin rpy="0.0 0.0 3.141592" xyz="0.0 0.0 0.0"/>
        </visual>
        <collision>
            <geometry>
                <mesh filename="package://ocs2_robotic_assets/resources/mcc/meshes/lower_leg.dae"/>
            </geometry>
            <origin rpy="0 0 3.141592" xyz="0 0 0"/>
        </collision>
    </link>






	    <joint name="LH_shank_fixed_LH_FOOT" type="fixed">
        <parent link="shank_hl"/>
        <child link="LH_FOOT"/>
        <origin rpy="0 0 0" xyz="-0.00001 0.01305 -0.19111"/>
    </joint>
    <!-- Foot link -->
    <link name="LH_FOOT">
        <!-- Adapter collision -->
        <collision>
            <origin rpy="0 0 0" xyz="0 0 0.168985"/>
            <geometry>
                <cylinder length="0.282504" radius="0.0175"/>
            </geometry>
        </collision>
        <!-- Foot collision -->
        <collision>
            <origin xyz="0 0 0.0225"/>
            <geometry>
                <sphere radius="0.03"/>
            </geometry>
        </collision>
        <inertial>
            <origin rpy="0 0 0" xyz="-0.00948 -0.00948 0.1468"/>
            <mass value="0.25"/>
            <inertia ixx="0.00317174097" ixy="-2.63048e-06" ixz="-6.815581e-05" iyy="0.00317174092" iyz="6.815583e-05" izz="8.319196e-05"/>
        </inertial>
</link>

	<joint name="RH_shank_fixed_RH_FOOT" type="fixed">
        <parent link="shank_hr"/>
        <child link="RH_FOOT"/>
        <origin rpy="0 0 0" xyz="-0.00001 0.01305 -0.19111"/>
    </joint>
    <!-- Foot link -->
    <link name="RH_FOOT">
        <!-- Adapter collision -->
        <collision>
            <origin rpy="0 0 0" xyz="0 0 0.168985"/>
            <geometry>
                <cylinder length="0.282504" radius="0.0175"/>
            </geometry>
        </collision>
        <!-- Foot collision -->
        <collision>
            <origin xyz="0 0 0.0225"/>
            <geometry>
                <sphere radius="0.03"/>
            </geometry>
        </collision>
        <inertial>
            <origin rpy="0 0 0" xyz="-0.00948 -0.00948 0.1468"/>
            <mass value="0.25"/>
            <inertia ixx="0.00317174097" ixy="-2.63048e-06" ixz="-6.815581e-05" iyy="0.00317174092" iyz="6.815583e-05" izz="8.319196e-05"/>
        </inertial>
</link>

	<joint name="LF_shank_fixed_LF_FOOT" type="fixed">
		<parent link="shank_fl"/>
        <child link="LF_FOOT"/>
        <origin rpy="0 0 0" xyz="-0.00001 0.01305 -0.19111"/>
    </joint>
    <!-- Foot link -->
    <link name="LF_FOOT">
        <!-- Adapter collision -->
        <collision>
            <origin rpy="0 0 0" xyz="0 0 0.168985"/>
            <geometry>
                <cylinder length="0.282504" radius="0.0175"/>
            </geometry>
        </collision>
        <!-- Foot collision -->
        <collision>
            <origin xyz="0 0 0.0225"/>
            <geometry>
                <sphere radius="0.03"/>
            </geometry>
        </collision>
        <inertial>
            <origin rpy="0 0 0" xyz="-0.00948 -0.00948 0.1468"/>
            <mass value="0.25"/>
            <inertia ixx="0.00317174097" ixy="-2.63048e-06" ixz="-6.815581e-05" iyy="0.00317174092" iyz="6.815583e-05" izz="8.319196e-05"/>
        </inertial>
</link>

	<joint name="RF_shank_fixed_RF_FOOT" type="fixed">
        <parent link="shank_fr"/>
        <child link="RF_FOOT"/>
        <origin rpy="0 0 0" xyz="-0.00001 0.01305 -0.19111"/>
    </joint>
    <!-- Foot link -->
    <link name="RF_FOOT">
        <!-- Adapter collision -->
        <collision>
            <origin rpy="0 0 0" xyz="0 0 0.168985"/>
            <geometry>
                <cylinder length="0.282504" radius="0.0175"/>
            </geometry>
        </collision>
        <!-- Foot collision -->
        <collision>
            <origin xyz="0 0 0.0225"/>
            <geometry>
                <sphere radius="0.03"/>
            </geometry>
        </collision>
        <inertial>
            <origin rpy="0 0 0" xyz="-0.00948 -0.00948 0.1468"/>
            <mass value="0.25"/>
            <inertia ixx="0.00317174097" ixy="-2.63048e-06" ixz="-6.815581e-05" iyy="0.00317174092" iyz="6.815583e-05" izz="8.319196e-05"/>
        </inertial>
    </link>








</robot>
